{"uuid":"08d243f2-8de1-47f8-ab69-7a8b277df03f","historyId":"45ca6ab2e569b4b485a1a3fd086a9ada","fullName":"TatvaCare.LoginTest.enterInvalidLoginCredentialsAndClickOnLoginButton","labels":[{"name":"package","value":"TatvaCare.LoginTest"},{"name":"testClass","value":"TatvaCare.LoginTest"},{"name":"testMethod","value":"enterInvalidLoginCredentialsAndClickOnLoginButton"},{"name":"parentSuite","value":"Default Suite"},{"name":"suite","value":"TatvaCare"},{"name":"subSuite","value":"TatvaCare.LoginTest"},{"name":"host","value":"DESKTOP-AU7IRSP"},{"name":"thread","value":"9068@DESKTOP-AU7IRSP.main(1)"},{"name":"framework","value":"testng"},{"name":"language","value":"java"},{"name":"story","value":"inValid mobile number and Password"},{"name":"severity","value":"normal"}],"links":[],"name":"Login with invalid credentials. ","status":"failed","statusDetails":{"known":false,"muted":false,"flaky":false,"message":"expected [We can't seem to find your account3] but found [validationMessage]","trace":"java.lang.AssertionError: expected [We can't seem to find your account3] but found [validationMessage]\r\n\tat org.testng.Assert.fail(Assert.java:110)\r\n\tat org.testng.Assert.failNotEquals(Assert.java:1413)\r\n\tat org.testng.Assert.assertEqualsImpl(Assert.java:149)\r\n\tat org.testng.Assert.assertEquals(Assert.java:131)\r\n\tat org.testng.Assert.assertEquals(Assert.java:655)\r\n\tat org.testng.Assert.assertEquals(Assert.java:665)\r\n\tat TatvaCare.LoginTest.enterInvalidLoginCredentialsAndClickOnLoginButton(LoginTest.java:47)\r\n\tat sun.reflect.NativeMethodAccessorImpl.invoke0(Native Method)\r\n\tat sun.reflect.NativeMethodAccessorImpl.invoke(NativeMethodAccessorImpl.java:62)\r\n\tat sun.reflect.DelegatingMethodAccessorImpl.invoke(DelegatingMethodAccessorImpl.java:43)\r\n\tat java.lang.reflect.Method.invoke(Method.java:498)\r\n\tat org.testng.internal.invokers.MethodInvocationHelper.invokeMethod(MethodInvocationHelper.java:135)\r\n\tat org.testng.internal.invokers.TestInvoker.invokeMethod(TestInvoker.java:673)\r\n\tat org.testng.internal.invokers.TestInvoker.invokeTestMethod(TestInvoker.java:220)\r\n\tat org.testng.internal.invokers.MethodRunner.runInSequence(MethodRunner.java:50)\r\n\tat org.testng.internal.invokers.TestInvoker$MethodInvocationAgent.invoke(TestInvoker.java:945)\r\n\tat org.testng.internal.invokers.TestInvoker.invokeTestMethods(TestInvoker.java:193)\r\n\tat org.testng.internal.invokers.TestMethodWorker.invokeTestMethods(TestMethodWorker.java:146)\r\n\tat org.testng.internal.invokers.TestMethodWorker.run(TestMethodWorker.java:128)\r\n\tat java.util.ArrayList.forEach(ArrayList.java:1257)\r\n\tat org.testng.TestRunner.privateRun(TestRunner.java:808)\r\n\tat org.testng.TestRunner.run(TestRunner.java:603)\r\n\tat org.testng.SuiteRunner.runTest(SuiteRunner.java:429)\r\n\tat org.testng.SuiteRunner.runSequentially(SuiteRunner.java:423)\r\n\tat org.testng.SuiteRunner.privateRun(SuiteRunner.java:383)\r\n\tat org.testng.SuiteRunner.run(SuiteRunner.java:326)\r\n\tat org.testng.SuiteRunnerWorker.runSuite(SuiteRunnerWorker.java:52)\r\n\tat org.testng.SuiteRunnerWorker.run(SuiteRunnerWorker.java:95)\r\n\tat org.testng.TestNG.runSuitesSequentially(TestNG.java:1249)\r\n\tat org.testng.TestNG.runSuitesLocally(TestNG.java:1169)\r\n\tat org.testng.TestNG.runSuites(TestNG.java:1092)\r\n\tat org.testng.TestNG.run(TestNG.java:1060)\r\n\tat com.intellij.rt.testng.IDEARemoteTestNG.run(IDEARemoteTestNG.java:66)\r\n\tat com.intellij.rt.testng.RemoteTestNGStarter.main(RemoteTestNGStarter.java:105)\r\n"},"stage":"finished","description":"Verify that validations message is displayed when user try to login with invalide credential","steps":[],"attachments":[],"parameters":[],"start":1691048743030,"stop":1691048758355}